<?xml version="1.0" ?>

<robot name="orion5">

  <link name="world"/>

  <joint name="world_fixed_joint" type="fixed">
    <origin rpy="0 0 0" xyz="0.0 0.0 0.0"/>
    <parent link="world"/>
    <child link="base_link"/>
  </joint>

  <material name="black">
    <color rgba="0.2 0.2 0.2 1.0"/>
  </material>
  <material name="gray">
    <color rgba="0.7 0.7 0.7 1.0"/>
  </material>
  <material name="blue">
    <color rgba="0.1 0.5 0.7 1.0"/>
  </material>

  <link name="base_link">
    <inertial>
      <origin rpy="0 0 0" xyz="0.00000 0.00169 0.02699"/>
      <mass value="0.43234"/>
      <inertia ixx="0.00108" ixy="0.00002" ixz="0.00000" iyy="0.00063" iyz="-0.00004" izz="0.00144"/>
    </inertial>
    <visual>
      <origin rpy="0 0 1.57080" xyz="0 0 0"/>
      <geometry>
        <mesh filename="package://orion5_humble_description/meshes/stl/base_link.stl"/>
      </geometry>
      <material name="blue"/>
    </visual>
    <collision>
      <origin rpy="0 0 1.57080" xyz="0 0 0"/>
      <geometry>
        <mesh filename="package://orion5_humble_description/meshes/stl/base_link.stl"/>
      </geometry>
    </collision>
  </link>

  <joint name="joint_1" type="revolute">
    <origin rpy="0 0 0" xyz="0 0 0"/>
    <parent link="base_link"/>
    <child link="link_1"/>
    <axis xyz="0 0 1"/>
    <limit effort="87" lower="-3.14" upper="3.14" velocity="1.57"/>
    <dynamics damping="0.1" friction="0.1"/>
  </joint>

  <link name="link_1">
    <inertial>
      <origin rpy="0 0 0" xyz="-0.00001 -0.00518 0.12742"/>
      <mass value="1.49770"/>
      <inertia ixx="0.00534" ixy="0.00007" ixz="-0.00005" iyy="0.00429" iyz="0.00042" izz="0.00403"/>
    </inertial>
    <visual>
      <origin rpy="0 0 -1.57080" xyz="0 0 0.05375"/>
      <geometry>
        <mesh filename="package://orion5_humble_description/meshes/stl/link_1.stl"/>
      </geometry>
      <material name="black"/>
    </visual>
    <collision>
      <origin rpy="0 0 -1.57080" xyz="0 0 0.05375"/>
      <geometry>
        <mesh filename="package://orion5_humble_description/meshes/stl/link_1.stl"/>
      </geometry>
    </collision>
  </link>

  <joint name="joint_2" type="revolute">
    <origin rpy="1.57080 0 0" xyz="0 0 0.12200"/>
    <parent link="link_1"/>
    <child link="link_2"/>
    <axis xyz="0 0 1"/>
    <limit effort="87" lower="-3.14" upper="3.14" velocity="1.57"/>
    <dynamics damping="0.1" friction="0.1"/>
  </joint>

  <link name="link_2">
    <inertial>
      <origin rpy="0 0 0" xyz="0.00000 0.17648 0.14370"/>
      <mass value="3.95670"/>
      <inertia ixx="0.10620" ixy="0.00007" ixz="0.00010" iyy="0.10302" iyz="-0.00106" izz="0.00923"/>
    </inertial>
    <visual>
      <origin rpy="0 0 0" xyz="0 0 0.06300"/>
      <geometry>
        <mesh filename="package://orion5_humble_description/meshes/stl/link_2.stl"/>
      </geometry>
      <material name="black"/>
    </visual>
    <collision>
      <origin rpy="0 0 0" xyz="0 0 0.06300"/>
      <geometry>
        <mesh filename="package://orion5_humble_description/meshes/stl/link_2.stl"/>
      </geometry>
    </collision>
  </link>

  <joint name="joint_3" type="revolute">
    <origin rpy="0 0 -1.57080" xyz="0 0.42100 0"/>
    <parent link="link_2"/>
    <child link="link_3"/>
    <axis xyz="0 0 1"/>
    <limit effort="52" lower="-3.14" upper="3.14" velocity="1.57"/>
    <dynamics damping="0.1" friction="0.1"/>
  </joint>

  <link name="link_3">
    <inertial>
      <origin rpy="0 0 0" xyz="-0.20718 0.00000 0.02333"/>
      <mass value="1.08680"/>
      <inertia ixx="0.02873" ixy="0.00000" ixz="-0.00005" iyy="0.02832" iyz="-0.00127" izz="0.00131"/>
    </inertial>
    <visual>
      <origin rpy="-3.14159 0 1.57080" xyz="0 0 0.08650"/>
      <geometry>
        <mesh filename="package://orion5_humble_description/meshes/stl/link_3.stl"/>
      </geometry>
      <material name="black"/>
    </visual>
    <collision>
      <origin rpy="-3.14159 0 1.57080" xyz="0 0 0.08650"/>
      <geometry>
        <mesh filename="package://orion5_humble_description/meshes/stl/link_3.stl"/>
      </geometry>
    </collision>
  </link>

  <joint name="joint_4" type="revolute">
    <origin rpy="0 0 0" xyz="-0.42700 0 0"/>
    <parent link="link_3"/>
    <child link="link_4"/>
    <axis xyz="0 0 1"/>
    <limit effort="10" lower="-3.14" upper="3.14" velocity="1.57"/>
    <dynamics damping="0.1" friction="0.1"/>
  </joint>

  <link name="link_4">
    <inertial>
      <origin rpy="0 0 0" xyz="-0.00399 0.00000 0.11685"/>
      <mass value="0.50427"/>
      <inertia ixx="0.00073" ixy="0.00000" ixz="0.00000" iyy="0.00066" iyz="0.00001" izz="0.00049"/>
    </inertial>
    <visual>
      <origin rpy="0 0 -1.57080" xyz="0 0 0.06800"/>
      <geometry>
        <mesh filename="package://orion5_humble_description/meshes/stl/link_4.stl"/>
      </geometry>
      <material name="black"/>
    </visual>
    <collision>
      <origin rpy="0 0 -1.57080" xyz="0 0 0.06800"/>
      <geometry>
        <mesh filename="package://orion5_humble_description/meshes/stl/link_4.stl"/>
      </geometry>
    </collision>
  </link>

  <joint name="joint_5" type="revolute">
    <origin rpy="1.57080 0 -1.57080" xyz="0 0 0.12100"/>
    <parent link="link_4"/>
    <child link="link_5"/>
    <axis xyz="0 0 1"/>
    <limit effort="10" lower="-3.14" upper="3.14" velocity="1.57"/>
    <dynamics damping="0.1" friction="0.1"/>
  </joint>

  <link name="link_5">
    <inertial>
      <origin rpy="0 0 0" xyz="0.00000 0.00467 0.10098"/>
      <mass value="0.23998"/>
      <inertia ixx="0.00045" ixy="-0.00000" ixz="-0.00000" iyy="0.00023" iyz="-0.00001" izz="0.00041"/>
    </inertial>
    <visual>
      <origin rpy="0 0 1.57080" xyz="0 0 0.05200"/>
      <geometry>
        <mesh filename="package://orion5_humble_description/meshes/stl/link_5.stl"/>
      </geometry>
      <material name="black"/>
    </visual>
    <collision>
      <origin rpy="0 0 1.57080" xyz="0 0 0.05200"/>
      <geometry>
        <mesh filename="package://orion5_humble_description/meshes/stl/link_5.stl"/>
      </geometry>
    </collision>
  </link>

  <joint name="joint_6" type="revolute">
    <origin rpy="-1.57080 0 0" xyz="0 0 0.10500"/>
    <parent link="link_5"/>
    <child link="link_6"/>
    <axis xyz="0 0 1"/>
    <limit effort="10" lower="-3.14" upper="3.14" velocity="1.57"/>
    <dynamics damping="0.1" friction="0.1"/>
  </joint>

  <link name="link_6">
    <inertial>
      <origin rpy="0 0 0" xyz="0.00003 -0.00024 0.08347"/>
      <mass value="0.23998"/>
      <inertia ixx="0.00024" ixy="0.00000" ixz="0.00001" iyy="0.00029" iyz="-0.00001" izz="0.00014"/>
    </inertial>
    <visual>
      <origin rpy="0 0 0" xyz="0 0 0.05900"/>
      <geometry>
        <mesh filename="package://orion5_humble_description/meshes/stl/link_6.stl"/>
      </geometry>
      <material name="gray"/>
    </visual>
    <collision>
      <origin rpy="0 0 0" xyz="0 0 0.05900"/>
      <geometry>
        <mesh filename="package://orion5_humble_description/meshes/stl/link_6.stl"/>
      </geometry>
    </collision>
  </link>

  <joint name="tool0_fixed_joint" type="fixed">
    <origin rpy="0 0 0" xyz="0 0 0.1089"/>
    <parent link="link_6"/>
    <child link="tool0"/>
  </joint>

  <link name="tool0">
    <inertial>
      <origin rpy="0 0 0" xyz="0 0 0"/>
      <mass value="0.0"/>
      <inertia ixx="0" ixy="0" ixz="0" iyy="0" iyz="0" izz="0"/>
    </inertial>
  </link>

  <!-- Gazebo Ros Transmission -->
  <transmission name="j1_transmission">
    <type>transmission_interface/SimpleTransmission</type>
    <joint name="joint_1">
      <hardwareInterface>hardware_interface/EffortJointInterface</hardwareInterface>
    </joint>
    <actuator name="j1_actuator">
      <hardwareInterface>hardware_interface/EffortJointInterface</hardwareInterface>
      <mechanicalReduction>1</mechanicalReduction>
    </actuator>
  </transmission>
  <transmission name="j2_transmission">
    <type>transmission_interface/SimpleTransmission</type>
    <joint name="joint_2">
      <hardwareInterface>hardware_interface/EffortJointInterface</hardwareInterface>
    </joint>
    <actuator name="j2_actuator">
      <hardwareInterface>hardware_interface/EffortJointInterface</hardwareInterface>
      <mechanicalReduction>1</mechanicalReduction>
    </actuator>
  </transmission>
  <transmission name="j3_transmission">
    <type>transmission_interface/SimpleTransmission</type>
    <joint name="joint_3">
      <hardwareInterface>hardware_interface/EffortJointInterface</hardwareInterface>
    </joint>
    <actuator name="j3_actuator">
      <hardwareInterface>hardware_interface/EffortJointInterface</hardwareInterface>
      <mechanicalReduction>1</mechanicalReduction>
    </actuator>
  </transmission>
  <transmission name="j4_transmission">
    <type>transmission_interface/SimpleTransmission</type>
    <joint name="joint_4">
      <hardwareInterface>hardware_interface/EffortJointInterface</hardwareInterface>
    </joint>
    <actuator name="j4_actuator">
      <hardwareInterface>hardware_interface/EffortJointInterface</hardwareInterface>
      <mechanicalReduction>1</mechanicalReduction>
    </actuator>
  </transmission>
  <transmission name="j5_transmission">
    <type>transmission_interface/SimpleTransmission</type>
    <joint name="joint_5">
      <hardwareInterface>hardware_interface/EffortJointInterface</hardwareInterface>
    </joint>
    <actuator name="j5_actuator">
      <hardwareInterface>hardware_interface/EffortJointInterface</hardwareInterface>
      <mechanicalReduction>1</mechanicalReduction>
    </actuator>
  </transmission>
  <transmission name="j6_transmission">
    <type>transmission_interface/SimpleTransmission</type>
    <joint name="joint_6">
      <hardwareInterface>hardware_interface/EffortJointInterface</hardwareInterface>
    </joint>
    <actuator name="j6_actuator">
      <hardwareInterface>hardware_interface/EffortJointInterface</hardwareInterface>
      <mechanicalReduction>1</mechanicalReduction>
    </actuator>
  </transmission>

  <!-- Gazebo ROS Control Plugin -->
  <gazebo>
    <plugin filename="libgazebo_ros_control.so" name="gazebo_ros_control"/>
  </gazebo>

  <!-- Gazebo Colors -->
  <gazebo reference="base_link">
    <material>Gazebo/SkyBlue</material>
    <mu1>0.2</mu1>
    <mu2>0.2</mu2>
    <selfCollide>true</selfCollide>
    <gravity>true</gravity>
  </gazebo>
  <gazebo reference="link_1">
    <material>Gazebo/DarkGray</material>
    <mu1>0.2</mu1>
    <mu2>0.2</mu2>
    <selfCollide>true</selfCollide>
  </gazebo>
  <gazebo reference="link_2">
    <material>Gazebo/DarkGray</material>
    <mu1>0.2</mu1>
    <mu2>0.2</mu2>
    <selfCollide>true</selfCollide>
  </gazebo>
  <gazebo reference="link_3">
    <material>Gazebo/DarkGray</material>
    <mu1>0.2</mu1>
    <mu2>0.2</mu2>
    <selfCollide>true</selfCollide>
  </gazebo>
  <gazebo reference="link_4">
    <material>Gazebo/DarkGray</material>
    <mu1>0.2</mu1>
    <mu2>0.2</mu2>
    <selfCollide>true</selfCollide>
  </gazebo>
  <gazebo reference="link_5">
    <material>Gazebo/DarkGray</material>
    <mu1>0.2</mu1>
    <mu2>0.2</mu2>
    <selfCollide>true</selfCollide>
  </gazebo>
  <gazebo reference="link_6">
    <material>Gazebo/Gray</material>
    <mu1>0.2</mu1>
    <mu2>0.2</mu2>
    <selfCollide>true</selfCollide>
  </gazebo>

  <!-- ROS 2 Humble ros2_control block (effort command interface) -->
  <ros2_control name="Orion5System" type="system">
    <hardware>
      <plugin>mujoco_pendulum::MujocoSystem</plugin>
      <param name="mujoco_model">orion5</param>
    </hardware>

    <joint name="joint_1">
      <command_interface name="effort"/>
      <state_interface name="position"/>
      <state_interface name="velocity"/>
      <state_interface name="effort"/>
    </joint>
    <joint name="joint_2">
      <command_interface name="effort"/>
      <state_interface name="position"/>
      <state_interface name="velocity"/>
      <state_interface name="effort"/>
    </joint>
    <joint name="joint_3">
      <command_interface name="effort"/>
      <state_interface name="position"/>
      <state_interface name="velocity"/>
      <state_interface name="effort"/>
    </joint>
    <joint name="joint_4">
      <command_interface name="effort"/>
      <state_interface name="position"/>
      <state_interface name="velocity"/>
      <state_interface name="effort"/>
    </joint>
    <joint name="joint_5">
      <command_interface name="effort"/>
      <state_interface name="position"/>
      <state_interface name="velocity"/>
      <state_interface name="effort"/>
    </joint>
    <joint name="joint_6">
      <command_interface name="effort"/>
      <state_interface name="position"/>
      <state_interface name="velocity"/>
      <state_interface name="effort"/>
    </joint>
  </ros2_control>

</robot>
